<?xml version='1.0'?>

<robot name="my_robot" xmlns:xacro="http://www.ros.org/wiki/xacro">
    
    <xacro:include filename="$(find my_robot)/urdf/my_robot.gazebo" />

    <link name="robot_footprint"></link>

    <joint name="robot_footprint_joint" type="fixed">
        <origin xyz="0 0 0" rpy="0 0 0" />
        <parent link="robot_footprint"/>
	    <child link="chassis"/>
    </joint>

    <link name="chassis">
        <pose>0 0 0.1 0 0 0</pose>

        <inertial>
            <mass value="15.0"/>
            <origin xyz="0.0 0 0" rpy="0 0 0"/>
            <inertia
                ixx="0.1" ixy="0" ixz="0"
                iyy="0.1" iyz="0"
                izz="0.1"
                />
        </inertial>

        <collision name="collision">
            <origin xyz="0 0 0" rpy="0 0 0"/>
            <geometry>
                <box size=".4 .2 .1"/>
            </geometry>
        </collision>

        <visual name="chassis_visual">
            <origin xyz="0 0 0" rpy="0 0 0 "/>
            <geometry>
                <box size=".4 .2 .1"/>
            </geometry>
        </visual>

        <collision name="back_caster_collision">
            <origin xyz="-0.15 0 -0.05"/>
            <geometry>
                <sphere radius="0.0499"/>
            </geometry>
        </collision>

        <visual name="back_caster_visual">
            <origin xyz="-0.15 0 -0.05"/>
            <geometry>
                <sphere radius="0.05"/>
            </geometry>
        </visual>

        <collision name="front_caster_collision">
            <origin xyz="0.15 0 -0.05" rpy=" 0 0 0 "/>
            <geometry>
                <sphere radius="0.0499"/>
            </geometry>
        </collision>

        <visual name="front_caster_visual">
            <origin xyz="0.15 0 -0.05" rpy="0 0 0"/>
            <geometry>
                <sphere radius="0.05"/>
            </geometry>
        </visual>

    </link>

    <joint name="body_joint" type="fixed">
        <origin xyz="0 0 0.1" rpy="0 0 0" />
        <parent link="chassis"/>
	<child link="body"/>
    </joint>

     <link name="body">

        <inertial>
            <mass value="10.0"/>
            <origin xyz="0.0 0 0" rpy="0 0 0"/>
            <inertia
                ixx="0.1" ixy="0" ixz="0"
                iyy="0.1" iyz="0"
                izz="0.1"
                />
        </inertial>

        <collision>
            <origin xyz="0 0 0" rpy="0 0 0"/>
            <geometry>
                <box size=".2 .2 .3"/>
            </geometry>
        </collision>

        <visual>
            <origin xyz="0 0 0" rpy="0 0 0 "/>
            <geometry>
                <box size=".2 .2 .3"/>
            </geometry>
           
        </visual>

    </link>

    <joint name="head_joint" type="fixed">
        <origin xyz="0 0 0.2" rpy="0 0 0" />
        <parent link="body"/>
	<child link="head"/>
    </joint>


    <link name="head">

        <inertial>
            <mass value="1.0"/>
            <origin xyz="0.0 0 0" rpy="0 0 0"/>
            <inertia
                ixx="0.1" ixy="0" ixz="0"
                iyy="0.1" iyz="0"
                izz="0.1"
                />
        </inertial>

        <collision>
            <origin xyz="0 0 0" rpy="0 0 0"/>
            <geometry>
                <box size=".1 .1 .1"/>
            </geometry>
        </collision>

        <visual>
            <origin xyz="0 0 0" rpy="0 0 0 "/>
            <geometry>
                <box size=".1 .1 .1"/>
            </geometry>
            
        </visual>

    </link>

    <joint name="left_arm_joint" type="fixed">
        <origin xyz="0.05 0.1 0.1" rpy="0 1.25 0" />
        <parent link="body"/>
	<child link="left_arm"/>
    </joint>


    <link name="left_arm">

        <inertial>
            <mass value="1.0"/>
            <origin xyz="0.0 0 0" rpy="0 0 0"/>
            <inertia
                ixx="0.1" ixy="0" ixz="0"
                iyy="0.1" iyz="0"
                izz="0.1"
                />
        </inertial>

        <collision>
            <origin xyz="0 0 0" rpy="0 0 0"/>
            <geometry>
                <box size=".05 .05 .2"/>
            </geometry>
        </collision>

        <visual>
            <origin xyz="0 0 0" rpy="0 0 0 "/>
            <geometry>
                <box size=".05 .05 .2"/>
            </geometry>
            
        </visual>

    </link>

    <joint name="right_arm_joint" type="fixed">
        <origin xyz="0.05 -0.1 0.1" rpy="0 1.25 0" />
        <parent link="body"/>
	<child link="right_arm"/>
    </joint>


    <link name="right_arm">

        <inertial>
            <mass value="1.0"/>
            <origin xyz="0.0 0 0" rpy="0 0 0"/>
            <inertia
                ixx="0.1" ixy="0" ixz="0"
                iyy="0.1" iyz="0"
                izz="0.1"
                />
        </inertial>

        <collision>
            <origin xyz="0 0 0" rpy="0 0 0"/>
            <geometry>
                <box size=".05 .05 .2"/>
            </geometry>
        </collision>

        <visual>
            <origin xyz="0 0 0" rpy="0 0 0 "/>
            <geometry>
                <box size=".05 .05 .2"/>
            </geometry>
            
        </visual>

    </link>

    <link name="right_wheel">

        <collision>
            <origin xyz="0 0 0" rpy="0 1.5707 1.5707"/>
            <geometry>
                <cylinder radius="0.1" length="0.05"/>
            </geometry>
        </collision>
        
        <inertial>
            <mass value="5"/>
            <origin xyz="0 0 0" rpy="0 1.5707 1.5707"/>
            <inertia
            ixx="0.1" ixy="0" ixz="0"
            iyy="0.1" iyz="0"
            izz="0.1" 
            />
        </inertial>

        <visual>
            <origin xyz="0 0 0" rpy="0 1.5707 1.5707"/>
            <geometry>
                <cylinder radius="0.1" length="0.05"/>
            </geometry>
        </visual>
    
    </link>

    

    <link name="left_wheel">

        <collision>
            <origin xyz="0 0 0" rpy="0 1.5707 1.5707"/>
            <geometry>
                <cylinder radius="0.1" length="0.05"/>
            </geometry>
        </collision>
        
        <inertial>
            <mass value="5"/>
            <origin xyz="0 0 0" rpy="0 1.5707 1.5707"/>
            <inertia
            ixx="0.1" ixy="0" ixz="0"
            iyy="0.1" iyz="0"
            izz="0.1" 
            />
        </inertial>

        <visual>
            <origin xyz="0 0 0" rpy="0 1.5707 1.5707"/>
            <geometry>
                <cylinder radius="0.1" length="0.05"/>
            </geometry>
        </visual>

    </link>

        <gazebo reference="left_wheel">
            <material>Gazebo/Black</material>
        </gazebo>
        
        <gazebo reference="right_wheel">
            <material>Gazebo/Black</material>
        </gazebo>
        
        <gazebo reference="head">
            <material>Gazebo/Blue</material>
        </gazebo>
        
        <gazebo reference="body">
            <material>Gazebo/Yellow</material>
        </gazebo>

        <gazebo reference="left_arm">
            <material>Gazebo/Red</material>
        </gazebo>
        
        <gazebo reference="right_arm">
            <material>Gazebo/Red</material>
        </gazebo>
        
        <gazebo reference="chassis">
            <material>Gazebo/Green</material>
        </gazebo>

    <joint name="left_wheel_hinge" type="continuous">
        <origin xyz="0 0.15 0" rpy="0 0 0"/>
        <child link="left_wheel"/>
        <parent link="chassis"/>
        <axis xyz="0 1 0" rpy="0 0 0"/>
        <limit effort="10000" velocity="1000"/>
        <dynamics damping="1.0" friction="1.0"/>
    </joint>

    <joint name="right_wheel_hinge" type="continuous">
        <origin xyz="0 -0.15 0" rpy="0 0 0"/>
        <child link="right_wheel"/>
        <parent link="chassis"/>
        <axis xyz="0 1 0" rpy="0 0 0"/>
        <limit effort="10000" velocity="1000"/>
        <dynamics damping="1.0" friction="1.0"/>
    </joint>

    <link name="camera">
        <collision>
            <origin xyz="0 0 0" rpy="0 0 0"/>
            <geometry>
                <box size="0.05 0.05 0.05"/>
            </geometry>
        </collision>

        <inertial>
            <origin xyz="0 0 0" rpy="0 0 0"/>
            <mass value="0.1"/>
            <inertia
                ixx="1e-6" ixy="0" ixz="0"
                iyy="1e-6" iyz="0"
                izz="1e-6"
                />
        </inertial>

        <visual>
            <origin xyz="0 0 0" rpy="0 0 0"/>
            <geometry>
                <box size="0.05 0.05 0.05"/>
            </geometry>
        </visual>

    </link>

    <joint name="camera_joint" type="fixed">
        <origin xyz="0.2 0 0.0" rpy="0 0 0"/>
        <parent link="chassis"/>
        <child link="camera"/>
        <axis xyz="0 1 0"/>
    </joint>

   <link name="left_ear">
        <collision>
            <origin xyz="0 0 0" rpy="0 0 0"/>
            <geometry>
                <box size="0.05 0.05 0.05"/>
            </geometry>
        </collision>

        <inertial>
            <origin xyz="0 0 0" rpy="0 0 0"/>
            <mass value="0.1"/>
            <inertia
                ixx="1e-6" ixy="0" ixz="0"
                iyy="1e-6" iyz="0"
                izz="1e-6"
                />
        </inertial>

        <visual>
            <origin xyz="0 0 0" rpy="0 0 0"/>
            <geometry>
                <box size="0.03 0.03 0.03"/>
            </geometry>
        </visual>

    </link>

    <joint name="left_ear_joint" type="fixed">
        <origin xyz="0.0 0.05 0.0" rpy="0 0 1.57"/>
        <parent link="head"/>
        <child link="left_ear"/>
        <axis xyz="0 1 0"/>
    </joint>

    <link name="right_ear">
        <collision>
            <origin xyz="0 0 0" rpy="0 0 0"/>
            <geometry>
                <box size="0.03 0.03 0.03"/>
            </geometry>
        </collision>

        <inertial>
            <origin xyz="0 0 0" rpy="0 0 0"/>
            <mass value="0.1"/>
            <inertia
                ixx="1e-6" ixy="0" ixz="0"
                iyy="1e-6" iyz="0"
                izz="1e-6"
                />
        </inertial>

        <visual>
            <origin xyz="0 0 0" rpy="0 0 0"/>
            <geometry>
                <box size="0.05 0.05 0.05"/>
            </geometry>
        </visual>

    </link>

    <joint name="right_ear_joint" type="fixed">
        <origin xyz="0.0 -0.05 0.0" rpy="0 0 -1.57"/>
        <parent link="head"/>
        <child link="right_ear"/>
        <axis xyz="0 1 0"/>
    </joint>


    <link name="hokuyo">
        <collision>
            <origin xyz="0 0 0" rpy="0 0 0"/>
            <geometry>
                <box size="0.1 0.1 0.1"/>
            </geometry>
        </collision>

        <inertial>
            <origin xyz="0 0 0" rpy="0 0 0"/>
            <mass value="1e-5"/>
            <inertia 
                ixx="1e-6" ixy="0" ixz="0"
                iyy="1e-6" iyz="0"
                izz="1e-6"
                />
        </inertial>

        <visual>
            <origin xyz="0 0 0" rpy="0 0 0"/>
            <geometry>
                <mesh filename="package://my_robot/meshes/hokuyo.dae"/>
            </geometry>
        </visual>

    </link>

    <joint name="hokuyo_joint" type="fixed">
        <origin xyz="0.15 0 0.1" rpy="0 0 0"/>
        <axis xyz="0 1 0"/>
        <parent link="chassis"/>
        <child link="hokuyo"/>
    </joint>




</robot>



